Workbook

Sheet Payback
H1: TUB PLANT PAYBACK CALCULATOR
H2: 4 TPH COOKED TUB PLANT — VAN BUREN, ARKANSAS
H3: Ref. proposal MCE-Q-2610-FCO-R1 · October 20, 2026
A6: Enter your numbers in the yellow cells (blue text). Everything else calculates. Ingredient prices and formulas are on the Formulations tab.
A8: INPUTS
A9: MCE price ($) | B9: 1517299 | C9: Proposal MCE-Q-2610-FCO-R1: equipment, engineering and start-up services
A10: Installation by others ($) | B10: 0 | C10: Enter your contractor estimate for installation, electrical and freight
A11: Tons per year | B11: 5000 | C11: Total tub production, all products
A12: Tub size (lb) | B12: 225 | C12: Basis for tub count
A13: Tub, lid and label ($/tub) | B13: 14 | C13: Your container cost
A14: Operators on the line | B14: 4 | C14: One shift
A15: Loaded labor rate ($/hr) | B15: 28 | C15: Wages plus benefits
A16: Hours per operator per year | B16: 2080 | C16: One shift, full year
A17: Energy ($/tub) | B17: 1 | C17: Gas and electric, estimate
A18: Maintenance (% of MCE price per year) | B18: 0.03 | C18: Parts and maintenance labor, estimate
A19: Cook yield (finished ÷ batch weight) | B19: 0.9 | C19: Moisture driven off in the cook, estimate
A20: Tubs per year (calculated) | B20: =IFERROR(B11*2000/B12,0)
A22: Product | B22: Share of volume | C22: Current buy price ($/tub)
A23: 30-13 type | B23: 0.5 | C23: 115
A24: 38 HI-E type | B24: 0.25 | C24: 125
A25: 17 +Mag type | B25: 0.25 | C25: 105
A26: Mix total (should be 100%) | B26: =SUM(B23:B25)
A28: COST TO MAKE vs. BUY, PER TUB
B29: 30-13 type | C29: 38 HI-E type | D29: 17 +Mag type
A30: Ingredients (Formulations tab) | B30: =Formulations!C24 | C30: =Formulations!D24 | D30: =Formulations!E24
A31: Tub, lid and label | B31: =$B$13 | C31: =$B$13 | D31: =$B$13
A32: Labor | B32: =IFERROR($B$14*$B$15*$B$16/$B$20,0) | C32: =IFERROR($B$14*$B$15*$B$16/$B$20,0) | D32: =IFERROR($B$14*$B$15*$B$16/$B$20,0)
A33: Energy | B33: =$B$17 | C33: =$B$17 | D33: =$B$17
A34: Maintenance | B34: =IFERROR($B$9*$B$18/$B$20,0) | C34: =IFERROR($B$9*$B$18/$B$20,0) | D34: =IFERROR($B$9*$B$18/$B$20,0)
A35: Cost to make | B35: =SUM(B30:B34) | C35: =SUM(C30:C34) | D35: =SUM(D30:D34)
A36: Current buy price | B36: =$C$23 | C36: =$C$24 | D36: =$C$25
A37: Savings per tub | B37: =B36-B35 | C37: =C36-C35 | D37: =D36-D35
A39: PAYBACK
A40: Savings per tub, mix-weighted | B40: =IFERROR(($B$23*B37+$B$24*C37+$B$25*D37)/SUM($B$23:$B$25),0)
A41: Annual savings | B41: =B40*B20
A42: Total investment (MCE price + installation) | B42: =B9+B10
A43: Simple payback (months) | B43: =IF(B41>0,12*B42/B41,"No payback")
A44: 5-year net savings | B44: =5*B41-B42
A45: 10-year net savings | B45: =10*B41-B42
F47: Helper values
...

Sheet Formulations
F1: ESTIMATED FORMULATIONS
F2: 4 TPH COOKED TUB PLANT — VAN BUREN, ARKANSAS
F3: Ref. proposal MCE-Q-2610-FCO-R1 · October 20, 2026
A6: Illustrative batch formulas built to the guaranteed analysis on comparable RangeLand labels. Your nutritionist sets final formulas. Edit prices and percentages in the yellow cells.
A8: INGREDIENTS
A9: Ingredient | B9: Delivered $/ton | C9: 30-13 type | D9: 38 HI-E type | E9: 17 +Mag type
A10: Cane molasses | B10: 240 | C10: 0.52 | D10: 0.445 | E10: 0.52
A11: Soybean meal 48% | B11: 340 | C11: 0.1 | D11: 0.09 | E11: 0.12
A12: Cottonseed meal 41% | B12: 320 | C12: 0.08 | D12: 0.07 | E12: 0.06
A13: Feather meal | B13: 550 | C13: 0.06 | D13: 0.06 | E13: 0.04
A14: Distillers grains (DDGS) | B14: 190 | C14: 0.03 | D14: 0.03 | E14: 0.06
A15: Urea, feed grade | B15: 550 | C15: 0.046 | D15: 0.071 | E15: 0
A16: Fat, animal or vegetable | B16: 1000 | C16: 0.04 | D16: 0.11 | E16: 0.04
A17: Dicalcium phosphate | B17: 850 | C17: 0.055 | D17: 0.055 | E17: 0.055
A18: Monocalcium phosphate | B18: 900 | C18: 0.015 | D18: 0.015 | E18: 0.015
A19: Calcium carbonate | B19: 60 | C19: 0.015 | D19: 0.015 | E19: 0.005
A20: Magnesium oxide | B20: 750 | C20: 0.019 | D20: 0.019 | E20: 0.065
A21: Sodium hydroxide 50% | B21: 700 | C21: 0.005 | D21: 0.005 | E21: 0.005
A22: Trace mineral / vitamin premix | B22: 2000 | C22: 0.015 | D22: 0.015 | E22: 0.015
A23: Batch total (should be 100%) | C23: =SUM(C10:C22) | D23: =SUM(D10:D22) | E23: =SUM(E10:E22)
A24: Ingredients per tub ($) | C24: =IFERROR(C26*Payback!$B$12/2000,0) | D24: =IFERROR(D26*Payback!$B$12/2000,0) | E24: =IFERROR(E26*Payback!$B$12/2000,0)
A25: Batch cost ($/ton) | C25: =SUMPRODUCT($B$10:$B$22,C10:C22) | D25: =SUMPRODUCT($B$10:$B$22,D10:D22) | E25: =SUMPRODUCT($B$10:$B$22,E10:E22)
A26: Finished cost after cook ($/ton) | C26: =IFERROR(C25/Payback!$B$19,0) | D26: =IFERROR(D25/Payback!$B$19,0) | E26: =IFERROR(E25/Payback!$B$19,0)
A28: Ingredient prices are delivered estimates for October 2026. Replace with your own purchase prices.

Sheet Notes
D1: NOTES
D2: 4 TPH COOKED TUB PLANT — VAN BUREN, ARKANSAS
D3: Ref. proposal MCE-Q-2610-FCO-R1 · October 20, 2026
A6: This calculator is a budgeting tool prepared by Midwest Custom Engineering, Inc. for Farmers Cooperative.
A7: Formulations are illustrative, built to the guaranteed analysis on comparable published labels. A ruminant nutritionist sets the final formulas during FEED.
A8: Ingredient prices are delivered estimates for October 2026. Replace them with your own purchase prices.
A9: Default buy prices are assumptions. Retail for a 225 lb RangeLand 30-13 tub ran $125–$200 in October 2026 (NRS, Tractor Supply).
A10: Results exclude building work, utilities to the plant, working capital and taxes. Enter installation on the Payback tab.
A11: Payback uses the annual average; peak-season months run ahead of it.
A12: Questions: Jason Shipley, President · jason@usemce.com · 772-200-4060 · cell 620-200-9109
