Workbook

Sheet README
B1: MCE DRYER HEAT & MASS BALANCE CALCULATOR · Rev A · 8 Sep 2026
B3: What this is: a rebuilt, formula-driven replacement for the calculation half of Prozus report NT-HMB-2025-001 Rev 0 (the Input/CALC/COMB/FLOW/DESIGN/Burner/Emiss. sheets). Every number recalculates from the Inputs sheet. Nothing is pasted.
B4: It follows MCE's own quoting method (Drying Rates Calculator, Feb 2026 notes): theoretical Btu per lb water from product inlet temperature, 1,750 Btu/lb with losses for a rotary drum, drum airflow at 350 fpm face velocity, 10 in WC fan static, 5,000 fpm duct velocity, and adds a rigorous energy balance beside it so the two can be compared on every job.
B6: HOW TO USE
B7: 1. Enter the job on the Inputs sheet. Blue cells are inputs; black cells are formulas; green cells pull from another sheet; yellow cells are model data MCE still has to fill in.
B8: 2. Read the HMB sheet: mass balance, MCE duty vs rigorous duty, combustion, airflow, energy closure (must be zero).
B9: 3. Read the Equipment sheet: selected dryer model, burner, fan, duct, cyclone inlet, airlocks, annual fuel.
B10: 4. Flow sheet is the live schematic: burner, make-up air, mixed inlet gas, feed, drum, exhaust and cyclone, fan and stack, product, fines and the optional reactor, each block showing its current numbers. Summary sheet is the one-page hand-off for quoting. Metric sheet mirrors the key results in SI units. Emissions sheet gives potential-to-emit.
B11: 4b. Biochar Reactor sheet sizes a slow-pyrolysis or torrefaction rotary reactor on the dryer product (or a manual feed): char yield, volatiles energy, autothermal check, auxiliary fuel or surplus heat, reactor length by residence time and by indirect heat flux. Set the coupling switch on Inputs to Yes to credit the surplus against dryer fuel.
B12: 4c. Drum length is sized, not just checked: the HMB sheet gives the length required at the selected diameter for the residence-time and fill targets, and the Summary shows whether to extend past the standard length.
B13: 5. Dryer Models: ten standard single-pass sizes plus a custom row; ten triple-pass rows on the same shells with a placeholder airflow factor (yellow) plus a custom row; Z8 eight-pass rows from the original workbook. A model is selected automatically as the smallest of the chosen type that meets both airflow and evaporation with the design margin. Burners are sized to the heat loading; a burner cap is optional per row.
B15: WHAT WAS WRONG IN THE ORIGINAL (kept here so it is not repeated)
... B33: Prepared by MCE Engineering with Claude. Internal tool, not a customer document.

Sheet Summary
B1: DRYER SIZING SUMMARY · for quoting
B2: =Inputs!$C$4 -> LETEK DCG / Bachoco - chicken manure digestate, 140 MT/day (case A: 70% MC press cake)
B4: PROCESS
B5: Material | C5: =Inputs!$C$11 -> chicken manure digestate cake (screw-pressed)
B6: Wet feed | C6: =Inputs!$C$13 -> 6430 | D6: lb/hr
B7: Moisture in → out (wet basis) | C7: =TEXT(Inputs!$C$14,"0%")&" → "&TEXT(Inputs!$C$15,"0%") -> 70% → 15%
B8: Dried product | C8: =HMB!$C$7 -> 2269.4118 | D8: lb/hr
B9: Water evaporated | C9: =HMB!$C$9 -> 4160.5882 | D9: lb/hr
B10: Dryer type | C10: =Inputs!$C$28 -> Single-pass rotary drum
B11: Drum inlet / exhaust gas | C11: =TEXT(Inputs!$C$36,"0")&" / "&TEXT(Inputs!$C$38,"0") -> 900 / 230 | D11: °F
B12: HEAT
B13: Total Btu of system (MCE, 1,750 basis) | C13: =HMB!$C$16 -> 7.2810294 | D13: MMBtu/hr
B14: Rigorous check | C14: =HMB!$C$26 -> 6.6097759 | D14: MMBtu/hr
B15: Btu per lb water, rigorous | C15: =HMB!$C$27 -> 1588.6638 | D15: Btu/lb
B16: Check | C16: =HMB!$C$28 -> WITHIN 15% OF MCE FACTOR
B17: Fuel | C17: =Inputs!$C$30 -> Propane
B18: Purchased fuel | C18: =HMB!$C$34 -> 365.88087 | D18: lb/hr
B19: Reactor heat credited | C19: =HMB!$C$32/1000000 -> 0 | D19: MMBtu/hr
B20: DRYER
B21: Model | C21: =Equipment!$C$4 -> XD-96 (8'×40')
B22: Drum diameter | C22: =Equipment!$C$5 -> 8 | D22: ft
B23: Standard length | C23: =Equipment!$C$6 -> 40 | D23: ft
B24: Length to quote | C24: =HMB!$C$80 -> 40 | D24: ft
B25: Length note | C25: =HMB!$C$81 -> STANDARD LENGTH GIVES THE RETENTION TIME
B26: Residence time at quoted length and fill target | C26: =IF(ISNUMBER(HMB!$C$80),HMB!$C$80*PI()/4*Equipment!$C$5^2*Inputs!$C$22/(Inputs!$C$13/60/Inputs!$C$20),"") -> 103.18886 | D26: min
B27: Evaporative loading at standard length | C27: =HMB!$C$74 -> 2.0693068 | D27: lb/hr·ft³
B28: Airflow utilization | C28: =Equipment!$C$13 -> 0.73519971
B29: EQUIPMENT
B30: Burner, with margin | C30: =Equipment!$C$17 -> 8.7372353 | D30: MMBtu/hr
B31: Burner face area | C31: =Equipment!$C$19 -> 7281.0294 | D31: in²
B32: Exhaust fan | C32: =Equipment!$C$24 -> 12934.309 | D32: ACFM
B33: Fan static / motor | C33: =TEXT(Inputs!$C$45,"0.0")&" in WC / "&TEXT(Equipment!$C$27,"0")&" hp" -> 12.0 in WC / 50 hp
B34: Exhaust duct | C34: =Equipment!$C$29 -> 22 | D34: in
B35: Cyclone inlet area (for the cyclone calculator) | C35: =Equipment!$C$32 -> 564.40621 | D35: in²
B36: Discharge / infeed airlock | C36: =Equipment!$C$37&" / "&Equipment!$C$38 -> 1212 / 1212
B37: Infeed screw | C37: =Equipment!$C$39 -> 9 | D37: in
B38: ANNUAL
B39: Operating hours | C39: =Equipment!$C$41 -> 8400 | D39: h/yr
B40: Dried product | C40: =Equipment!$C$42 -> 9531.5294 | D40: tons/yr
B41: Purchased fuel energy | C41: =Equipment!$C$45 -> 61160.647 | D41: MMBtu/yr
...

Sheet Inputs
B1: INPUTS · blue = enter, black = calculated, green = from another sheet
B3: JOB | G3: DRYER TYPE | H3: Energy factor Btu/lb | I3: Note
B4: Case name | C4: LETEK DCG / Bachoco - chicken manure digestate, 140 MT/day (case A: 70% MC press cake) | E4: Shows on the Flow sheet, top left
B5: Customer | C5: LETEK DCG - Bachoco layer farms | E5: Flow sheet header, centre | G5: Single-pass rotary drum | H5: 1750 | I5: MCE standard, confirmed J. Shipley 9 Sep 2026
B6: Customer location | C6: Merida, Yucatan, Mexico | G6: Triple-pass rotary drum | H6: 1750 | I6: MCE standard, confirmed J. Shipley 9 Sep 2026
B7: Prepared by | C7: MCE Engineering | G7: Z8 eight-pass | H7: 1750 | I7: MCE standard, confirmed J. Shipley 9 Sep 2026
B8: Document number | C8: MCE-HMB-2026-002 | G8: Infrared | H8: 1500 | I8: 7 Feb 2026 notes
B9: Revision | C9: A | G9: Flash tube | H9: 1875 | I9: 1,850–1,900 per notes
B10: Date | C10: =TODAY() -> 46274 | E10: Formula; overwrite with a fixed date when issued
B11: Material | C11: chicken manure digestate cake (screw-pressed) | G11: FUEL TABLE
B12: MATERIAL AND THROUGHPUT | G12: Fuel | H12: HHV Btu/lb | I12: lb/ft³ | J12: Excess air | K12: Stoich air lb/lb | L12: H2O lb/lb fuel | M12: CO2 lb/lb fuel | N12: Source
B13: Wet feed rate | C13: 6430 | D13: lb/hr | E13: Enter wet feed OR set to =C? from dry product below; this is the governing input | G13: Natural Gas | H13: 22800 | I13: 0.044 | J13: 0.25 | K13: 16.33 | L13: 2.25 | M13: 2.75 | N13: Original Input F6:I6; stoich from original CALC G25
B14: Moisture in, wet basis | C14: 0.7 | E14: Fraction, e.g. 0.50 | G14: Propane | H14: 19900 | I14: 0.048 | J14: 0.3 | K14: 15.7 | L14: 1.63 | M14: 3 | N14: Original Input F8:I8; stoich standard
B15: Moisture out, wet basis | C15: 0.15 | G15: #2 Fuel Oil | H15: 18500 | I15: 55.6 | J15: 0.5 | K15: 14.3 | L15: 1.14 | M15: 3.2 | N15: Original Input F9:I9; stoich standard
B16: Product temperature in | C16: 85 | D16: °F | E16: Drying Rates Calculator uses 40 °F for winter feed; 60 °F typical | G16: Biomass (wet, 8,500) | H16: 8500 | I16: 15 | J16: 1 | K16: 5.9 | L16: 0.9 | M16: 1.74 | N16: Original Input F7:I7 had 200% excess air; reduced to 100%, confirm
B17: Product temperature out | C17: 180 | D17: °F | E17: Dried material discharge temperature | G17: Dry Wood | H17: 8000 | I17: 12 | J17: 1.3 | K17: 5.82 | L17: 0.58 | M17: 1.74 | N17: Original Input F10:I10; stoich, H2O, CO2 from original COMB L32, L42+L54, L41
B18: Specific heat of dry solids | C18: 0.3 | D18: Btu/lb·°F | E18: Dry wood 0.32–0.40; original sheets used 0.55 (wet) and 0.23 (Prozus) | G18: Biogas 55% CH4 | H18: 7400 | I18: 0.075 | J18: 0.15 | K18: 5.3 | L18: 0.69 | M18: 1.54 | N18: Placeholder for dual-fuel jobs; enter analysis when known
B19: Bulk density, dried product | C19: 30 | D19: lb/ft³ | E19: Used for airlock and screw sizing
B20: Bulk density, wet feed | C20: 55 | D20: lb/ft³
B21: Drum residence time target | C21: 20 | D21: min | E21: Sizes the drum length; 10–30 min single pass, longer for fluffy or sticky product
B22: Drum fill target | C22: 0.1 | D22: fraction of drum volume | E22: 5–15% normal; sets the length needed for the residence time
B23: SITE
B24: Elevation | C24: 30 | D24: ft
B25: Ambient temperature | C25: 85 | D25: °F
B26: Ambient humidity | C26: 0.018 | D26: lb H2O/lb dry air | E26: Florida summer ~0.015; original had 0.002
B27: DRYER AND FUEL
B28: Dryer type | C28: Single-pass rotary drum | E28: Pick from list (dropdown): Single-pass rotary drum, Triple-pass rotary drum, Z8 eight-pass, Infrared, Flash tube
B29: MCE energy factor | C29: =INDEX($H$5:$H$9,MATCH(C28,$G$5:$G$9,0)) -> 1750 | D29: Btu/lb water | E29: From the dryer type table at right
B30: Fuel | C30: Propane | E30: Pick from list (dropdown): see fuel table at right
B31: Fuel heating value | C31: =INDEX($H$13:$H$18,MATCH(C30,$G$13:$G$18,0)) -> 19900 | D31: Btu/lb
B32: Excess air at burner | C32: =INDEX($J$13:$J$18,MATCH(C30,$G$13:$G$18,0)) -> 0.3 | D32: fraction
B33: Stoichiometric air | C33: =INDEX($K$13:$K$18,MATCH(C30,$G$13:$G$18,0)) -> 15.7 | D33: lb air/lb fuel
B34: Water formed per lb fuel | C34: =INDEX($L$13:$L$18,MATCH(C30,$G$13:$G$18,0)) -> 1.63 | D34: lb H2O/lb fuel | E34: Includes fuel moisture for wood
B35: CO2 per lb fuel | C35: =INDEX($M$13:$M$18,MATCH(C30,$G$13:$G$18,0)) -> 3 | D35: lb/lb fuel
B36: Dryer inlet gas temperature | C36: 900 | D36: °F | E36: Design choice, up to the maximum below. Lower it for heat-sensitive product.
B37: Maximum drum inlet gas temperature | C37: 900 | D37: °F | E37: MCE design limit, J. Shipley 9 Sep 2026
B38: Dryer exhaust gas temperature | C38: 230 | D38: °F | E38: Original 180 °F; 200–230 °F for high-moisture feeds
B39: Combustion efficiency | C39: 0.9 | D39: fraction | E39: Original Input H3
B40: Shell and radiation loss | C40: 0.03 | D40: fraction of fired duty
B41: Air in-leakage at seals | C41: 0.1 | D41: fraction of hot gas | E41: Adds to exhaust volume only
...

Sheet Flow
C1: Prepared by: | G1: =Inputs!$C$7 -> MCE Engineering | AA1: =Inputs!$C$5 -> LETEK DCG - Bachoco layer farms | BG1: =Inputs!$C$10 -> 46274
AA2: =Inputs!$C$6 -> Merida, Yucatan, Mexico
C3: =Inputs!$C$4 -> LETEK DCG / Bachoco - chicken manure digestate, 140 MT/day (case A: 70% MC press cake) | U3: DEHYDRATION SYSTEM MASS-ENERGY BALANCE
BD4: Exhaust Gases
E5: =Inputs!$C$13/2000 -> 3.215 | J5: =" TPH wet "&Inputs!$C$11 -> TPH wet chicken manure digestate cake (screw-pressed) | BD5: =HMB!$C$53 -> 12934.309 | BK5: ACFM
E6: =Inputs!$C$13/(Inputs!$C$20*27) -> 4.3299663 | J6: =" C.Y./hr @ "&TEXT(Inputs!$C$20*27,"0")&" lb/C.Y. and "&TEXT(Inputs!$C$14,"0%")&" moisture" -> C.Y./hr @ 1485 lb/C.Y. and 70% moisture | BD6: =Equipment!$C$27 -> 50 | BK6: hp fan
E7: =IF(ISNUMBER(Equipment!$C$5),TEXT(Equipment!$C$5,"0")&"x"&TEXT(HMB!$C$80,"0"),"") -> 8x40 | J7: =" "&Inputs!$C$28&" · "&Equipment!$C$4 -> Single-pass rotary drum · XD-96 (8'×40')
C8: Elevation | E8: =Inputs!$C$24 -> 30 | J8: feet (above sea level) | BD8: Dryer Outlet Gases
BD9: =HMB!$C$53 -> 12934.309 | BK9: ACFM
C10: Fuel to Burner | AA10: =HMB!$C$27 -> 1588.6638 | AG10: Btu's/lb evaporation (rigorous) | BD10: =Inputs!$C$38 -> 230 | BK10: deg F
C11: =Inputs!$C$30 -> Propane
C12: =Inputs!$C$31 -> 19900 | J12: Btu/lb
C13: =HMB!$C$34 -> 365.88087 | J13: lb/hr | O13: Make-Up Air | AB13: Mixed Inlet Gases
C14: =HMB!$C$33/1000000 -> 7.2810294 | J14: MMBtu/hr | O14: =HMB!$C$56 -> 5704.0355 | T14: SCFM | AB14: =HMB!$C$55 -> 7444.8153 | AH14: SCFM
O15: =Inputs!$C$25 -> 85 | T15: deg F | AB15: =Inputs!$C$36 -> 900 | AH15: deg F
X24: Wet Feed
X25: =Inputs!$C$14 -> 0.7 | AE25: moisture
C26: Combustion Air | X26: =HMB!$C$5 -> 1929 | AE26: lb/hr solids | AL26: EVAPORATION RATE
C27: =HMB!$C$57 -> 1674.7945 | J27: ACFM | X27: =HMB!$C$6 -> 4501 | AE27: lb/hr water | AL27: =HMB!$C$9 -> 4160.5882 | AQ27: LB/HR H2O
C28: =Inputs!$C$25 -> 85 | J28: deg F | X28: =Inputs!$C$13 -> 6430 | AE28: lb/hr total
C29: =Inputs!$C$32 -> 0.3 | J29: X-S air | AK29: =Equipment!$C$4&" · "&TEXT(HMB!$C$80,"0")&" ft long · "&TEXT(Equipment!$C$17,"0.0")&" MMBtu/hr burner" -> XD-96 (8'×40') · 40 ft long · 8.7 MMBtu/hr burner
AM30: Dry Fuel (product burned)
AM31: =HMB!$C$58 -> 0 | AS31: lb/hr total
BD32: Dry Material
BD33: =Inputs!$C$15 -> 0.15 | BK33: moisture
AM34: Net Dry Product | BD34: =HMB!$C$5 -> 1929 | BK34: lb/hr solids
AM35: =HMB!$C$59 -> 2269.4118 | AS35: lb/hr total | BD35: =HMB!$C$8 -> 340.41176 | BK35: lb/hr water
BD36: =HMB!$C$7 -> 2269.4118 | BK36: lb/hr total
BD37: =Inputs!$C$17 -> 180 | BK37: deg F
C47: =Inputs!$C$8&" Rev "&Inputs!$C$9&" · FLOW" -> MCE-HMB-2026-002 Rev A · FLOW | AF47: MIDWEST CUSTOM ENGINEERING, INC. · Stuart, FL · usemce.com | BG47: Page 1/1

Sheet HMB
B1: HEAT AND MASS BALANCE · imperial
B3: MASS BALANCE
B4: Wet feed | C4: =Inputs!$C$13 -> 6430 | D4: lb/hr
B5: Dry solids | C5: =Inputs!$C$13*(1-Inputs!$C$14) -> 1929 | D5: lb/hr
B6: Water in with feed | C6: =Inputs!$C$13*Inputs!$C$14 -> 4501 | D6: lb/hr
B7: Dried product | C7: =HMB!$C$5/(1-Inputs!$C$15) -> 2269.4118 | D7: lb/hr
B8: Water remaining in product | C8: =HMB!$C$7-HMB!$C$5 -> 340.41176 | D8: lb/hr
B9: Water evaporated | C9: =HMB!$C$6-HMB!$C$8 -> 4160.5882 | D9: lb/hr | E9: Governs everything below
B10: Water evaporated | C10: =HMB!$C$9/8.345 -> 498.57259 | D10: gal/hr
B11: Product | C11: =HMB!$C$7/2000 -> 1.1347059 | D11: TPH
B12: MCE METHOD (Drying Rates Calculator)
B13: Theoretical energy per lb water | C13: =1.01*(212-Inputs!$C$16)+970.4 -> 1098.67 | D13: Btu/lb | E13: Sensible to 212 °F plus latent 970.4
B14: Energy factor with losses | C14: =Inputs!$C$29 -> 1750 | D14: Btu/lb
B15: Total Btu of system (MCE) | C15: =HMB!$C$9*HMB!$C$14 -> 7281029.4 | D15: Btu/hr | E15: The number quoting has always used
B16: Total Btu of system (MCE) | C16: =HMB!$C$15/1000000 -> 7.2810294 | D16: MMBtu/hr
B17: RIGOROUS BALANCE (check on the MCE factor)
B18: Heat dry solids | C18: =HMB!$C$5*Inputs!$C$18*(Inputs!$C$17-Inputs!$C$16) -> 54976.5 | D18: Btu/hr
B19: Heat water remaining in product | C19: =HMB!$C$8*1*(Inputs!$C$17-Inputs!$C$16) -> 32339.118 | D19: Btu/hr
B20: Heat evaporated water to 212 °F | C20: =HMB!$C$9*1.01*(212-Inputs!$C$16) -> 533678.65 | D20: Btu/hr
B21: Vaporize | C21: =HMB!$C$9*970.4 -> 4037434.8 | D21: Btu/hr
B22: Superheat vapor to exhaust temperature | C22: =HMB!$C$9*0.45*(Inputs!$C$38-212) -> 33700.765 | D22: Btu/hr | E22: Negative if exhaust is below 212 °F, as in the original
B23: Product heating requirement | C23: =SUM($C$18:$C$22) -> 4692129.9 | D23: Btu/hr
B24: Share of released heat given up by the gas | C24: =Inputs!$C$39*(Inputs!$C$36-Inputs!$C$38)/(Inputs!$C$36-Inputs!$C$25) -> 0.7398773 | D24: fraction | E24: (T_in − T_exhaust)/(T_in − T_ambient) × combustion efficiency
B25: Fired duty, rigorous | C25: =HMB!$C$23/(HMB!$C$24-Inputs!$C$40) -> 6609775.9 | D25: Btu/hr | E25: Closed form; replaces the unconverged iteration in the original CALC
B26: Fired duty, rigorous | C26: =HMB!$C$25/1000000 -> 6.6097759 | D26: MMBtu/hr
B27: Btu per lb water, rigorous | C27: =HMB!$C$25/HMB!$C$9 -> 1588.6638 | D27: Btu/lb
B28: Check against MCE factor | C28: =IF(ABS(HMB!$C$27/HMB!$C$14-1)<=0.15,"WITHIN 15% OF MCE FACTOR",IF(HMB!$C$27>HMB!$C$14,"RIGOROUS IS HIGHER: raise inlet temp or accept higher fuel","RIGOROUS IS LOWER: MCE factor is conservative here")) -> WITHIN 15% OF MCE FACTOR | E28: Original FLOW G8 showed 11,788 Btu/lb and nobody looked
B29: Design fired duty used downstream | C29: =MAX(HMB!$C$15,HMB!$C$25) -> 7281029.4 | D29: Btu/hr | E29: Larger of the two, by policy
B30: COMBUSTION
B31: Fuel rate | C31: =HMB!$C$29/Inputs!$C$31 -> 365.88087 | D31: lb/hr
B32: Reactor surplus heat credited | C32: =IF(Inputs!$C$55="Yes",MAX(0,MIN(HMB!$C$29,'Biochar Reactor'!$C$48)),0) -> 0 | D32: Btu/hr | E32: From the Biochar Reactor sheet when coupling is Yes
B33: Purchased fuel duty | C33: =HMB!$C$29-HMB!$C$32 -> 7281029.4 | D33: Btu/hr
B34: Purchased fuel rate | C34: =HMB!$C$33/Inputs!$C$31 -> 365.88087 | D34: lb/hr
B35: Fuel volume (all fired) | C35: =HMB!$C$31/INDEX(Inputs!$I$13:$I$18,MATCH(Inputs!$C$30,Inputs!$G$13:$G$18,0))/60 -> 127.04197 | D35: ft³/min | E35: Gas fuels: ft³/min at standard; solid fuels: bulk ft³/min
B36: Combustion air | C36: =HMB!$C$31*Inputs!$C$33*(1+Inputs!$C$32) -> 7467.6287 | D36: lb/hr
B37: Products of combustion | C37: =HMB!$C$31+HMB!$C$36 -> 7833.5095 | D37: lb/hr
B38: Water in products of combustion | C38: =HMB!$C$31*Inputs!$C$34+HMB!$C$36*Inputs!$C$26 -> 730.80314 | D38: lb/hr
B39: Adiabatic products temperature, approx. | C39: =Inputs!$C$25+HMB!$C$29*Inputs!$C$39/(0.27*HMB!$C$37) -> 3183.2407 | D39: °F | E39: cp 0.27 average; sanity only
B40: DRYER GAS FLOW
B41: Hot gas to dryer at inlet temperature | C41: =HMB!$C$29*Inputs!$C$39/(0.24*(Inputs!$C$36-Inputs!$C$25)) -> 33501.669 | D41: lb/hr | E41: Products of combustion plus dilution air, dry basis
...

Sheet Dryer Models
B1: DRYER MODELS · one table, three types · yellow = MCE to fill
B2: Reference evaporative loading for the volume-limited rating, lb/hr·ft³: | K2: Single-pass | L2: 6 | M2: Triple-pass | N2: 8 | O2: Z8 | P2: 8
B3: Burners are sized to the heat loading, so drums rate on volume × reference loading; enter a burner cap only if a drum has a fixed burner. Design ACFM for single-pass = cross-section × face velocity. Triple-pass rows use the same shells times the triple-pass factor on Inputs until Baker-Rullman ratings are entered (yellow). Z8 uses the entered ACFM.
B5: Type | C5: Model | D5: Dia ft | E5: Length ft | F5: Cross-section ft² | G5: Volume ft³ | H5: Design ACFM | I5: Burner cap MMBtu/hr (optional) | J5: Evap at burner cap lb/hr | K5: Evap at volume loading lb/hr | L5: Rated evap lb/hr | M5: Meets job? (row) | N5: Burner at rated evap MMBtu/hr | O5: Overall L×W×H in | P5: Fan hp | Q5: Source / status
B6: Single-pass rotary drum | C6: XD-36 (3'×12') | D6: 3 | E6: 12 | F6: =IF(OR(D6="",E6=""),"",PI()/4*D6^2) -> 7.0685835 | G6: =IF(OR(D6="",E6=""),"",F6*E6) -> 84.823002 | H6: =IF(F6="","",F6*Inputs!$C$44) -> 2474.0042 | J6: =IF(I6="","",I6*1000000/Inputs!$C$29) | K6: =IF(G6="","",G6*$L$2) -> 508.93801 | L6: =IF(K6="","",IF(J6="",K6,MIN(J6,K6))) -> 508.93801 | M6: =IF(AND(B6=Inputs!$C$28,H6<>"",L6<>"",H6>=HMB!$C$53*(1+Inputs!$C$51),L6>=HMB!$C$9*(1+Inputs!$C$51)),ROW(),99999) -> 99999 | N6: =IF(L6="","",L6*Inputs!$C$29/1000000) -> 0.89064152 | Q6: MCE standard size, J. Shipley 9 Sep 2026; burner sized to heat loading
B7: Single-pass rotary drum | C7: XD-36 (3'×20') | D7: 3 | E7: 20 | F7: =IF(OR(D7="",E7=""),"",PI()/4*D7^2) -> 7.0685835 | G7: =IF(OR(D7="",E7=""),"",F7*E7) -> 141.37167 | H7: =IF(F7="","",F7*Inputs!$C$44) -> 2474.0042 | J7: =IF(I7="","",I7*1000000/Inputs!$C$29) | K7: =IF(G7="","",G7*$L$2) -> 848.23002 | L7: =IF(K7="","",IF(J7="",K7,MIN(J7,K7))) -> 848.23002 | M7: =IF(AND(B7=Inputs!$C$28,H7<>"",L7<>"",H7>=HMB!$C$53*(1+Inputs!$C$51),L7>=HMB!$C$9*(1+Inputs!$C$51)),ROW(),99999) -> 99999 | N7: =IF(L7="","",L7*Inputs!$C$29/1000000) -> 1.4844025 | Q7: MCE standard size, J. Shipley 9 Sep 2026; burner sized to heat loading
B8: Single-pass rotary drum | C8: XD-48 (4'×20') | D8: 4 | E8: 20 | F8: =IF(OR(D8="",E8=""),"",PI()/4*D8^2) -> 12.566371 | G8: =IF(OR(D8="",E8=""),"",F8*E8) -> 251.32741 | H8: =IF(F8="","",F8*Inputs!$C$44) -> 4398.2297 | J8: =IF(I8="","",I8*1000000/Inputs!$C$29) | K8: =IF(G8="","",G8*$L$2) -> 1507.9645 | L8: =IF(K8="","",IF(J8="",K8,MIN(J8,K8))) -> 1507.9645 | M8: =IF(AND(B8=Inputs!$C$28,H8<>"",L8<>"",H8>=HMB!$C$53*(1+Inputs!$C$51),L8>=HMB!$C$9*(1+Inputs!$C$51)),ROW(),99999) -> 99999 | N8: =IF(L8="","",L8*Inputs!$C$29/1000000) -> 2.6389378 | Q8: MCE standard size, J. Shipley 9 Sep 2026; burner sized to heat loading
B9: Single-pass rotary drum | C9: XD-60 (5'×25') | D9: 5 | E9: 25 | F9: =IF(OR(D9="",E9=""),"",PI()/4*D9^2) -> 19.634954 | G9: =IF(OR(D9="",E9=""),"",F9*E9) -> 490.87385 | H9: =IF(F9="","",F9*Inputs!$C$44) -> 6872.2339 | J9: =IF(I9="","",I9*1000000/Inputs!$C$29) | K9: =IF(G9="","",G9*$L$2) -> 2945.2431 | L9: =IF(K9="","",IF(J9="",K9,MIN(J9,K9))) -> 2945.2431 | M9: =IF(AND(B9=Inputs!$C$28,H9<>"",L9<>"",H9>=HMB!$C$53*(1+Inputs!$C$51),L9>=HMB!$C$9*(1+Inputs!$C$51)),ROW(),99999) -> 99999 | N9: =IF(L9="","",L9*Inputs!$C$29/1000000) -> 5.1541754 | Q9: MCE standard size, J. Shipley 9 Sep 2026; burner sized to heat loading
B10: Single-pass rotary drum | C10: XD-72 (6'×30') | D10: 6 | E10: 30 | F10: =IF(OR(D10="",E10=""),"",PI()/4*D10^2) -> 28.274334 | G10: =IF(OR(D10="",E10=""),"",F10*E10) -> 848.23002 | H10: =IF(F10="","",F10*Inputs!$C$44) -> 9896.0169 | J10: =IF(I10="","",I10*1000000/Inputs!$C$29) | K10: =IF(G10="","",G10*$L$2) -> 5089.3801 | L10: =IF(K10="","",IF(J10="",K10,MIN(J10,K10))) -> 5089.3801 | M10: =IF(AND(B10=Inputs!$C$28,H10<>"",L10<>"",H10>=HMB!$C$53*(1+Inputs!$C$51),L10>=HMB!$C$9*(1+Inputs!$C$51)),ROW(),99999) -> 99999 | N10: =IF(L10="","",L10*Inputs!$C$29/1000000) -> 8.9064152 | Q10: MCE standard size, J. Shipley 9 Sep 2026; burner sized to heat loading
B11: Single-pass rotary drum | C11: XD-84 (7'×35') | D11: 7 | E11: 35 | F11: =IF(OR(D11="",E11=""),"",PI()/4*D11^2) -> 38.48451 | G11: =IF(OR(D11="",E11=""),"",F11*E11) -> 1346.9579 | H11: =IF(F11="","",F11*Inputs!$C$44) -> 13469.579 | J11: =IF(I11="","",I11*1000000/Inputs!$C$29) | K11: =IF(G11="","",G11*$L$2) -> 8081.7471 | L11: =IF(K11="","",IF(J11="",K11,MIN(J11,K11))) -> 8081.7471 | M11: =IF(AND(B11=Inputs!$C$28,H11<>"",L11<>"",H11>=HMB!$C$53*(1+Inputs!$C$51),L11>=HMB!$C$9*(1+Inputs!$C$51)),ROW(),99999) -> 99999 | N11: =IF(L11="","",L11*Inputs!$C$29/1000000) -> 14.143057 | Q11: MCE standard size, J. Shipley 9 Sep 2026; burner sized to heat loading
B12: Single-pass rotary drum | C12: XD-96 (8'×40') | D12: 8 | E12: 40 | F12: =IF(OR(D12="",E12=""),"",PI()/4*D12^2) -> 50.265482 | G12: =IF(OR(D12="",E12=""),"",F12*E12) -> 2010.6193 | H12: =IF(F12="","",F12*Inputs!$C$44) -> 17592.919 | J12: =IF(I12="","",I12*1000000/Inputs!$C$29) | K12: =IF(G12="","",G12*$L$2) -> 12063.716 | L12: =IF(K12="","",IF(J12="",K12,MIN(J12,K12))) -> 12063.716 | M12: =IF(AND(B12=Inputs!$C$28,H12<>"",L12<>"",H12>=HMB!$C$53*(1+Inputs!$C$51),L12>=HMB!$C$9*(1+Inputs!$C$51)),ROW(),99999) -> 12 | N12: =IF(L12="","",L12*Inputs!$C$29/1000000) -> 21.111503 | Q12: MCE standard size, J. Shipley 9 Sep 2026; burner sized to heat loading
B13: Single-pass rotary drum | C13: XD-120 (10'×50') | D13: 10 | E13: 50 | F13: =IF(OR(D13="",E13=""),"",PI()/4*D13^2) -> 78.539816 | G13: =IF(OR(D13="",E13=""),"",F13*E13) -> 3926.9908 | H13: =IF(F13="","",F13*Inputs!$C$44) -> 27488.936 | J13: =IF(I13="","",I13*1000000/Inputs!$C$29) | K13: =IF(G13="","",G13*$L$2) -> 23561.945 | L13: =IF(K13="","",IF(J13="",K13,MIN(J13,K13))) -> 23561.945 | M13: =IF(AND(B13=Inputs!$C$28,H13<>"",L13<>"",H13>=HMB!$C$53*(1+Inputs!$C$51),L13>=HMB!$C$9*(1+Inputs!$C$51)),ROW(),99999) -> 13 | N13: =IF(L13="","",L13*Inputs!$C$29/1000000) -> 41.233404 | Q13: MCE standard size, J. Shipley 9 Sep 2026; burner sized to heat loading
B14: Single-pass rotary drum | C14: XD-144 (12'×60') | D14: 12 | E14: 60 | F14: =IF(OR(D14="",E14=""),"",PI()/4*D14^2) -> 113.09734 | G14: =IF(OR(D14="",E14=""),"",F14*E14) -> 6785.8401 | H14: =IF(F14="","",F14*Inputs!$C$44) -> 39584.067 | J14: =IF(I14="","",I14*1000000/Inputs!$C$29) | K14: =IF(G14="","",G14*$L$2) -> 40715.041 | L14: =IF(K14="","",IF(J14="",K14,MIN(J14,K14))) -> 40715.041 | M14: =IF(AND(B14=Inputs!$C$28,H14<>"",L14<>"",H14>=HMB!$C$53*(1+Inputs!$C$51),L14>=HMB!$C$9*(1+Inputs!$C$51)),ROW(),99999) -> 14 | N14: =IF(L14="","",L14*Inputs!$C$29/1000000) -> 71.251321 | Q14: MCE standard size, J. Shipley 9 Sep 2026; burner sized to heat loading
B15: Single-pass rotary drum | C15: XD-156 (13'×60') | D15: 13 | E15: 60 | F15: =IF(OR(D15="",E15=""),"",PI()/4*D15^2) -> 132.73229 | G15: =IF(OR(D15="",E15=""),"",F15*E15) -> 7963.9374 | H15: =IF(F15="","",F15*Inputs!$C$44) -> 46456.301 | J15: =IF(I15="","",I15*1000000/Inputs!$C$29) | K15: =IF(G15="","",G15*$L$2) -> 47783.624 | L15: =IF(K15="","",IF(J15="",K15,MIN(J15,K15))) -> 47783.624 | M15: =IF(AND(B15=Inputs!$C$28,H15<>"",L15<>"",H15>=HMB!$C$53*(1+Inputs!$C$51),L15>=HMB!$C$9*(1+Inputs!$C$51)),ROW(),99999) -> 15 | N15: =IF(L15="","",L15*Inputs!$C$29/1000000) -> 83.621342 | Q15: MCE standard size, J. Shipley 9 Sep 2026; burner sized to heat loading
B16: Single-pass rotary drum | C16: Custom single-pass (enter dia × length) | F16: =IF(OR(D16="",E16=""),"",PI()/4*D16^2) | G16: =IF(OR(D16="",E16=""),"",F16*E16) | H16: =IF(F16="","",F16*Inputs!$C$44) | J16: =IF(I16="","",I16*1000000/Inputs!$C$29) | K16: =IF(G16="","",G16*$L$2) | L16: =IF(K16="","",IF(J16="",K16,MIN(J16,K16))) | M16: =IF(AND(B16=Inputs!$C$28,H16<>"",L16<>"",H16>=HMB!$C$53*(1+Inputs!$C$51),L16>=HMB!$C$9*(1+Inputs!$C$51)),ROW(),99999) -> 99999 | N16: =IF(L16="","",L16*Inputs!$C$29/1000000) | Q16: Any size can be built; enter drum OD and length
B17: Triple-pass rotary drum | C17: TP-36 (3'×12') | D17: 3 | E17: 12 | F17: =IF(OR(D17="",E17=""),"",PI()/4*D17^2) -> 7.0685835 | G17: =IF(OR(D17="",E17=""),"",F17*E17) -> 84.823002 | H17: =IF(F17="","",F17*Inputs!$C$44*Inputs!$C$53) -> 2474.0042 | J17: =IF(I17="","",I17*1000000/Inputs!$C$29) | K17: =IF(G17="","",G17*$N$2) -> 678.58401 | L17: =IF(K17="","",IF(J17="",K17,MIN(J17,K17))) -> 678.58401 | M17: =IF(AND(B17=Inputs!$C$28,H17<>"",L17<>"",H17>=HMB!$C$53*(1+Inputs!$C$51),L17>=HMB!$C$9*(1+Inputs!$C$51)),ROW(),99999) -> 99999 | N17: =IF(L17="","",L17*Inputs!$C$29/1000000) -> 1.187522 | Q17: MCE will match the Baker-Rullman triple-pass models; ACFM = OD cross-section × face velocity × triple-pass factor until their ratings are entered
B18: Triple-pass rotary drum | C18: TP-36 (3'×20') | D18: 3 | E18: 20 | F18: =IF(OR(D18="",E18=""),"",PI()/4*D18^2) -> 7.0685835 | G18: =IF(OR(D18="",E18=""),"",F18*E18) -> 141.37167 | H18: =IF(F18="","",F18*Inputs!$C$44*Inputs!$C$53) -> 2474.0042 | J18: =IF(I18="","",I18*1000000/Inputs!$C$29) | K18: =IF(G18="","",G18*$N$2) -> 1130.9734 | L18: =IF(K18="","",IF(J18="",K18,MIN(J18,K18))) -> 1130.9734 | M18: =IF(AND(B18=Inputs!$C$28,H18<>"",L18<>"",H18>=HMB!$C$53*(1+Inputs!$C$51),L18>=HMB!$C$9*(1+Inputs!$C$51)),ROW(),99999) -> 99999 | N18: =IF(L18="","",L18*Inputs!$C$29/1000000) -> 1.9792034 | Q18: MCE will match the Baker-Rullman triple-pass models; ACFM = OD cross-section × face velocity × triple-pass factor until their ratings are entered
B19: Triple-pass rotary drum | C19: TP-48 (4'×20') | D19: 4 | E19: 20 | F19: =IF(OR(D19="",E19=""),"",PI()/4*D19^2) -> 12.566371 | G19: =IF(OR(D19="",E19=""),"",F19*E19) -> 251.32741 | H19: =IF(F19="","",F19*Inputs!$C$44*Inputs!$C$53) -> 4398.2297 | J19: =IF(I19="","",I19*1000000/Inputs!$C$29) | K19: =IF(G19="","",G19*$N$2) -> 2010.6193 | L19: =IF(K19="","",IF(J19="",K19,MIN(J19,K19))) -> 2010.6193 | M19: =IF(AND(B19=Inputs!$C$28,H19<>"",L19<>"",H19>=HMB!$C$53*(1+Inputs!$C$51),L19>=HMB!$C$9*(1+Inputs!$C$51)),ROW(),99999) -> 99999 | N19: =IF(L19="","",L19*Inputs!$C$29/1000000) -> 3.5185838 | Q19: MCE will match the Baker-Rullman triple-pass models; ACFM = OD cross-section × face velocity × triple-pass factor until their ratings are entered
B20: Triple-pass rotary drum | C20: TP-60 (5'×25') | D20: 5 | E20: 25 | F20: =IF(OR(D20="",E20=""),"",PI()/4*D20^2) -> 19.634954 | G20: =IF(OR(D20="",E20=""),"",F20*E20) -> 490.87385 | H20: =IF(F20="","",F20*Inputs!$C$44*Inputs!$C$53) -> 6872.2339 | J20: =IF(I20="","",I20*1000000/Inputs!$C$29) | K20: =IF(G20="","",G20*$N$2) -> 3926.9908 | L20: =IF(K20="","",IF(J20="",K20,MIN(J20,K20))) -> 3926.9908 | M20: =IF(AND(B20=Inputs!$C$28,H20<>"",L20<>"",H20>=HMB!$C$53*(1+Inputs!$C$51),L20>=HMB!$C$9*(1+Inputs!$C$51)),ROW(),99999) -> 99999 | N20: =IF(L20="","",L20*Inputs!$C$29/1000000) -> 6.8722339 | Q20: MCE will match the Baker-Rullman triple-pass models; ACFM = OD cross-section × face velocity × triple-pass factor until their ratings are entered
B21: Triple-pass rotary drum | C21: TP-72 (6'×30') | D21: 6 | E21: 30 | F21: =IF(OR(D21="",E21=""),"",PI()/4*D21^2) -> 28.274334 | G21: =IF(OR(D21="",E21=""),"",F21*E21) -> 848.23002 | H21: =IF(F21="","",F21*Inputs!$C$44*Inputs!$C$53) -> 9896.0169 | J21: =IF(I21="","",I21*1000000/Inputs!$C$29) | K21: =IF(G21="","",G21*$N$2) -> 6785.8401 | L21: =IF(K21="","",IF(J21="",K21,MIN(J21,K21))) -> 6785.8401 | M21: =IF(AND(B21=Inputs!$C$28,H21<>"",L21<>"",H21>=HMB!$C$53*(1+Inputs!$C$51),L21>=HMB!$C$9*(1+Inputs!$C$51)),ROW(),99999) -> 99999 | N21: =IF(L21="","",L21*Inputs!$C$29/1000000) -> 11.87522 | Q21: MCE will match the Baker-Rullman triple-pass models; ACFM = OD cross-section × face velocity × triple-pass factor until their ratings are entered
B22: Triple-pass rotary drum | C22: TP-84 (7'×35') | D22: 7 | E22: 35 | F22: =IF(OR(D22="",E22=""),"",PI()/4*D22^2) -> 38.48451 | G22: =IF(OR(D22="",E22=""),"",F22*E22) -> 1346.9579 | H22: =IF(F22="","",F22*Inputs!$C$44*Inputs!$C$53) -> 13469.579 | J22: =IF(I22="","",I22*1000000/Inputs!$C$29) | K22: =IF(G22="","",G22*$N$2) -> 10775.663 | L22: =IF(K22="","",IF(J22="",K22,MIN(J22,K22))) -> 10775.663 | M22: =IF(AND(B22=Inputs!$C$28,H22<>"",L22<>"",H22>=HMB!$C$53*(1+Inputs!$C$51),L22>=HMB!$C$9*(1+Inputs!$C$51)),ROW(),99999) -> 99999 | N22: =IF(L22="","",L22*Inputs!$C$29/1000000) -> 18.85741 | Q22: MCE will match the Baker-Rullman triple-pass models; ACFM = OD cross-section × face velocity × triple-pass factor until their ratings are entered
B23: Triple-pass rotary drum | C23: TP-96 (8'×40') | D23: 8 | E23: 40 | F23: =IF(OR(D23="",E23=""),"",PI()/4*D23^2) -> 50.265482 | G23: =IF(OR(D23="",E23=""),"",F23*E23) -> 2010.6193 | H23: =IF(F23="","",F23*Inputs!$C$44*Inputs!$C$53) -> 17592.919 | J23: =IF(I23="","",I23*1000000/Inputs!$C$29) | K23: =IF(G23="","",G23*$N$2) -> 16084.954 | L23: =IF(K23="","",IF(J23="",K23,MIN(J23,K23))) -> 16084.954 | M23: =IF(AND(B23=Inputs!$C$28,H23<>"",L23<>"",H23>=HMB!$C$53*(1+Inputs!$C$51),L23>=HMB!$C$9*(1+Inputs!$C$51)),ROW(),99999) -> 99999 | N23: =IF(L23="","",L23*Inputs!$C$29/1000000) -> 28.14867 | Q23: MCE will match the Baker-Rullman triple-pass models; ACFM = OD cross-section × face velocity × triple-pass factor until their ratings are entered
B24: Triple-pass rotary drum | C24: TP-120 (10'×50') | D24: 10 | E24: 50 | F24: =IF(OR(D24="",E24=""),"",PI()/4*D24^2) -> 78.539816 | G24: =IF(OR(D24="",E24=""),"",F24*E24) -> 3926.9908 | H24: =IF(F24="","",F24*Inputs!$C$44*Inputs!$C$53) -> 27488.936 | J24: =IF(I24="","",I24*1000000/Inputs!$C$29) | K24: =IF(G24="","",G24*$N$2) -> 31415.927 | L24: =IF(K24="","",IF(J24="",K24,MIN(J24,K24))) -> 31415.927 | M24: =IF(AND(B24=Inputs!$C$28,H24<>"",L24<>"",H24>=HMB!$C$53*(1+Inputs!$C$51),L24>=HMB!$C$9*(1+Inputs!$C$51)),ROW(),99999) -> 99999 | N24: =IF(L24="","",L24*Inputs!$C$29/1000000) -> 54.977871 | Q24: MCE will match the Baker-Rullman triple-pass models; ACFM = OD cross-section × face velocity × triple-pass factor until their ratings are entered
B25: Triple-pass rotary drum | C25: TP-144 (12'×60') | D25: 12 | E25: 60 | F25: =IF(OR(D25="",E25=""),"",PI()/4*D25^2) -> 113.09734 | G25: =IF(OR(D25="",E25=""),"",F25*E25) -> 6785.8401 | H25: =IF(F25="","",F25*Inputs!$C$44*Inputs!$C$53) -> 39584.067 | J25: =IF(I25="","",I25*1000000/Inputs!$C$29) | K25: =IF(G25="","",G25*$N$2) -> 54286.721 | L25: =IF(K25="","",IF(J25="",K25,MIN(J25,K25))) -> 54286.721 | M25: =IF(AND(B25=Inputs!$C$28,H25<>"",L25<>"",H25>=HMB!$C$53*(1+Inputs!$C$51),L25>=HMB!$C$9*(1+Inputs!$C$51)),ROW(),99999) -> 99999 | N25: =IF(L25="","",L25*Inputs!$C$29/1000000) -> 95.001762 | Q25: MCE will match the Baker-Rullman triple-pass models; ACFM = OD cross-section × face velocity × triple-pass factor until their ratings are entered
B26: Triple-pass rotary drum | C26: TP-156 (13'×60') | D26: 13 | E26: 60 | F26: =IF(OR(D26="",E26=""),"",PI()/4*D26^2) -> 132.73229 | G26: =IF(OR(D26="",E26=""),"",F26*E26) -> 7963.9374 | H26: =IF(F26="","",F26*Inputs!$C$44*Inputs!$C$53) -> 46456.301 | J26: =IF(I26="","",I26*1000000/Inputs!$C$29) | K26: =IF(G26="","",G26*$N$2) -> 63711.499 | L26: =IF(K26="","",IF(J26="",K26,MIN(J26,K26))) -> 63711.499 | M26: =IF(AND(B26=Inputs!$C$28,H26<>"",L26<>"",H26>=HMB!$C$53*(1+Inputs!$C$51),L26>=HMB!$C$9*(1+Inputs!$C$51)),ROW(),99999) -> 99999 | N26: =IF(L26="","",L26*Inputs!$C$29/1000000) -> 111.49512 | Q26: MCE will match the Baker-Rullman triple-pass models; ACFM = OD cross-section × face velocity × triple-pass factor until their ratings are entered
B27: Triple-pass rotary drum | C27: Custom triple-pass (enter dia × length) | F27: =IF(OR(D27="",E27=""),"",PI()/4*D27^2) | G27: =IF(OR(D27="",E27=""),"",F27*E27) | H27: =IF(F27="","",F27*Inputs!$C$44*Inputs!$C$53) | J27: =IF(I27="","",I27*1000000/Inputs!$C$29) | K27: =IF(G27="","",G27*$N$2) | L27: =IF(K27="","",IF(J27="",K27,MIN(J27,K27))) | M27: =IF(AND(B27=Inputs!$C$28,H27<>"",L27<>"",H27>=HMB!$C$53*(1+Inputs!$C$51),L27>=HMB!$C$9*(1+Inputs!$C$51)),ROW(),99999) -> 99999 | N27: =IF(L27="","",L27*Inputs!$C$29/1000000) | Q27: Any size can be built
B28: Z8 eight-pass | C28: Z8 6'x24' | D28: 6 | E28: 24 | F28: =IF(OR(D28="",E28=""),"",PI()/4*D28^2) -> 28.274334 | G28: =IF(OR(D28="",E28=""),"",F28*E28) -> 678.58401 | H28: 7000 | J28: =IF(I28="","",I28*1000000/Inputs!$C$29) | K28: =IF(G28="","",G28*$P$2) -> 5428.6721 | L28: =IF(K28="","",IF(J28="",K28,MIN(J28,K28))) -> 5428.6721 | M28: =IF(AND(B28=Inputs!$C$28,H28<>"",L28<>"",H28>=HMB!$C$53*(1+Inputs!$C$51),L28>=HMB!$C$9*(1+Inputs!$C$51)),ROW(),99999) -> 99999 | N28: =IF(L28="","",L28*Inputs!$C$29/1000000) -> 9.5001762 | Q28: Original Input K8:L18 ACFM max
B29: Z8 eight-pass | C29: Z8 8'x35' | D29: 8 | E29: 35 | F29: =IF(OR(D29="",E29=""),"",PI()/4*D29^2) -> 50.265482 | G29: =IF(OR(D29="",E29=""),"",F29*E29) -> 1759.2919 | H29: 18000 | J29: =IF(I29="","",I29*1000000/Inputs!$C$29) | K29: =IF(G29="","",G29*$P$2) -> 14074.335 | L29: =IF(K29="","",IF(J29="",K29,MIN(J29,K29))) -> 14074.335 | M29: =IF(AND(B29=Inputs!$C$28,H29<>"",L29<>"",H29>=HMB!$C$53*(1+Inputs!$C$51),L29>=HMB!$C$9*(1+Inputs!$C$51)),ROW(),99999) -> 99999 | N29: =IF(L29="","",L29*Inputs!$C$29/1000000) -> 24.630086 | Q29: Original Input K8:L18 ACFM max
B30: Z8 eight-pass | C30: Z8 10'x40' | D30: 10 | E30: 40 | F30: =IF(OR(D30="",E30=""),"",PI()/4*D30^2) -> 78.539816 | G30: =IF(OR(D30="",E30=""),"",F30*E30) -> 3141.5927 | H30: 32000 | J30: =IF(I30="","",I30*1000000/Inputs!$C$29) | K30: =IF(G30="","",G30*$P$2) -> 25132.741 | L30: =IF(K30="","",IF(J30="",K30,MIN(J30,K30))) -> 25132.741 | M30: =IF(AND(B30=Inputs!$C$28,H30<>"",L30<>"",H30>=HMB!$C$53*(1+Inputs!$C$51),L30>=HMB!$C$9*(1+Inputs!$C$51)),ROW(),99999) -> 99999 | N30: =IF(L30="","",L30*Inputs!$C$29/1000000) -> 43.982297 | Q30: Original Input K8:L18 ACFM max
B31: Z8 eight-pass | C31: Z8 10'x50' | D31: 10 | E31: 50 | F31: =IF(OR(D31="",E31=""),"",PI()/4*D31^2) -> 78.539816 | G31: =IF(OR(D31="",E31=""),"",F31*E31) -> 3926.9908 | H31: 40000 | J31: =IF(I31="","",I31*1000000/Inputs!$C$29) | K31: =IF(G31="","",G31*$P$2) -> 31415.927 | L31: =IF(K31="","",IF(J31="",K31,MIN(J31,K31))) -> 31415.927 | M31: =IF(AND(B31=Inputs!$C$28,H31<>"",L31<>"",H31>=HMB!$C$53*(1+Inputs!$C$51),L31>=HMB!$C$9*(1+Inputs!$C$51)),ROW(),99999) -> 99999 | N31: =IF(L31="","",L31*Inputs!$C$29/1000000) -> 54.977871 | Q31: Original Input K8:L18 ACFM max
B32: Z8 eight-pass | C32: Z8 12'x50' | D32: 12 | E32: 50 | F32: =IF(OR(D32="",E32=""),"",PI()/4*D32^2) -> 113.09734 | G32: =IF(OR(D32="",E32=""),"",F32*E32) -> 5654.8668 | H32: 55000 | J32: =IF(I32="","",I32*1000000/Inputs!$C$29) | K32: =IF(G32="","",G32*$P$2) -> 45238.934 | L32: =IF(K32="","",IF(J32="",K32,MIN(J32,K32))) -> 45238.934 | M32: =IF(AND(B32=Inputs!$C$28,H32<>"",L32<>"",H32>=HMB!$C$53*(1+Inputs!$C$51),L32>=HMB!$C$9*(1+Inputs!$C$51)),ROW(),99999) -> 99999 | N32: =IF(L32="","",L32*Inputs!$C$29/1000000) -> 79.168135 | Q32: Original Input K8:L18 ACFM max
B33: Z8 eight-pass | C33: Z8 12'x60' | D33: 12 | E33: 60 | F33: =IF(OR(D33="",E33=""),"",PI()/4*D33^2) -> 113.09734 | G33: =IF(OR(D33="",E33=""),"",F33*E33) -> 6785.8401 | H33: 65000 | J33: =IF(I33="","",I33*1000000/Inputs!$C$29) | K33: =IF(G33="","",G33*$P$2) -> 54286.721 | L33: =IF(K33="","",IF(J33="",K33,MIN(J33,K33))) -> 54286.721 | M33: =IF(AND(B33=Inputs!$C$28,H33<>"",L33<>"",H33>=HMB!$C$53*(1+Inputs!$C$51),L33>=HMB!$C$9*(1+Inputs!$C$51)),ROW(),99999) -> 99999 | N33: =IF(L33="","",L33*Inputs!$C$29/1000000) -> 95.001762 | Q33: Original Input K8:L18 ACFM max
B34: Z8 eight-pass | C34: Z8 12'x70' | D34: 12 | E34: 70 | F34: =IF(OR(D34="",E34=""),"",PI()/4*D34^2) -> 113.09734 | G34: =IF(OR(D34="",E34=""),"",F34*E34) -> 7916.8135 | H34: 75000 | J34: =IF(I34="","",I34*1000000/Inputs!$C$29) | K34: =IF(G34="","",G34*$P$2) -> 63334.508 | L34: =IF(K34="","",IF(J34="",K34,MIN(J34,K34))) -> 63334.508 | M34: =IF(AND(B34=Inputs!$C$28,H34<>"",L34<>"",H34>=HMB!$C$53*(1+Inputs!$C$51),L34>=HMB!$C$9*(1+Inputs!$C$51)),ROW(),99999) -> 99999 | N34: =IF(L34="","",L34*Inputs!$C$29/1000000) -> 110.83539 | Q34: Original Input K8:L18 ACFM max
B35: Z8 eight-pass | C35: Z8 13'x60' | D35: 13 | E35: 60 | F35: =IF(OR(D35="",E35=""),"",PI()/4*D35^2) -> 132.73229 | G35: =IF(OR(D35="",E35=""),"",F35*E35) -> 7963.9374 | H35: 80000 | J35: =IF(I35="","",I35*1000000/Inputs!$C$29) | K35: =IF(G35="","",G35*$P$2) -> 63711.499 | L35: =IF(K35="","",IF(J35="",K35,MIN(J35,K35))) -> 63711.499 | M35: =IF(AND(B35=Inputs!$C$28,H35<>"",L35<>"",H35>=HMB!$C$53*(1+Inputs!$C$51),L35>=HMB!$C$9*(1+Inputs!$C$51)),ROW(),99999) -> 99999 | N35: =IF(L35="","",L35*Inputs!$C$29/1000000) -> 111.49512 | Q35: Original Input K8:L18 ACFM max
B36: Z8 eight-pass | C36: Z8 14'x70' | D36: 14 | E36: 70 | F36: =IF(OR(D36="",E36=""),"",PI()/4*D36^2) -> 153.93804 | G36: =IF(OR(D36="",E36=""),"",F36*E36) -> 10775.663 | H36: 90000 | J36: =IF(I36="","",I36*1000000/Inputs!$C$29) | K36: =IF(G36="","",G36*$P$2) -> 86205.302 | L36: =IF(K36="","",IF(J36="",K36,MIN(J36,K36))) -> 86205.302 | M36: =IF(AND(B36=Inputs!$C$28,H36<>"",L36<>"",H36>=HMB!$C$53*(1+Inputs!$C$51),L36>=HMB!$C$9*(1+Inputs!$C$51)),ROW(),99999) -> 99999 | N36: =IF(L36="","",L36*Inputs!$C$29/1000000) -> 150.85928 | Q36: Original Input K8:L18 ACFM max
B37: Z8 eight-pass | C37: Z8 15'x70' | D37: 15 | E37: 70 | F37: =IF(OR(D37="",E37=""),"",PI()/4*D37^2) -> 176.71459 | G37: =IF(OR(D37="",E37=""),"",F37*E37) -> 12370.021 | H37: 100000 | J37: =IF(I37="","",I37*1000000/Inputs!$C$29) | K37: =IF(G37="","",G37*$P$2) -> 98960.169 | L37: =IF(K37="","",IF(J37="",K37,MIN(J37,K37))) -> 98960.169 | M37: =IF(AND(B37=Inputs!$C$28,H37<>"",L37<>"",H37>=HMB!$C$53*(1+Inputs!$C$51),L37>=HMB!$C$9*(1+Inputs!$C$51)),ROW(),99999) -> 99999 | N37: =IF(L37="","",L37*Inputs!$C$29/1000000) -> 173.1803 | Q37: Original Input K8:L18 ACFM max

Sheet Equipment
B1: EQUIPMENT SELECTION · imperial
B3: DRYER
B4: Selected dryer (smallest of the chosen type that meets airflow and evaporation with margin) | C4: =IFERROR(INDEX('Dryer Models'!$C$6:$C$37,MATCH(MIN('Dryer Models'!$M$6:$M$37),'Dryer Models'!$M$6:$M$37,0)),"NO MODEL OF THIS TYPE MEETS THE JOB - fill ratings or pick another type") -> XD-96 (8'×40')
B5: Drum diameter | C5: =IFERROR(INDEX('Dryer Models'!$D$6:$D$37,MATCH(MIN('Dryer Models'!$M$6:$M$37),'Dryer Models'!$M$6:$M$37,0)),"") -> 8 | D5: ft
B6: Drum length | C6: =IFERROR(INDEX('Dryer Models'!$E$6:$E$37,MATCH(MIN('Dryer Models'!$M$6:$M$37),'Dryer Models'!$M$6:$M$37,0)),"") -> 40 | D6: ft
B7: Drum volume | C7: =IFERROR(INDEX('Dryer Models'!$G$6:$G$37,MATCH(MIN('Dryer Models'!$M$6:$M$37),'Dryer Models'!$M$6:$M$37,0)),0) -> 2010.6193 | D7: ft³
B8: Model design airflow | C8: =IFERROR(INDEX('Dryer Models'!$H$6:$H$37,MATCH(MIN('Dryer Models'!$M$6:$M$37),'Dryer Models'!$M$6:$M$37,0)),"") -> 17592.919 | D8: ACFM
B9: Model rated evaporation | C9: =IFERROR(INDEX('Dryer Models'!$L$6:$L$37,MATCH(MIN('Dryer Models'!$M$6:$M$37),'Dryer Models'!$M$6:$M$37,0)),"") -> 12063.716 | D9: lb/hr
B10: Model maximum burner | C10: =IFERROR(IF(INDEX('Dryer Models'!$I$6:$I$37,MATCH(MIN('Dryer Models'!$M$6:$M$37),'Dryer Models'!$M$6:$M$37,0))="","not entered",INDEX('Dryer Models'!$I$6:$I$37,MATCH(MIN('Dryer Models'!$M$6:$M$37),'Dryer Models'!$M$6:$M$37,0))),"") -> not entered | D10: MMBtu/hr
B11: Burner at model rated evaporation | C11: =IFERROR(INDEX('Dryer Models'!$N$6:$N$37,MATCH(MIN('Dryer Models'!$M$6:$M$37),'Dryer Models'!$M$6:$M$37,0)),"") -> 21.111503 | D11: MMBtu/hr | E11: What the drum can use at reference loading; the job burner below is what it needs
B12: Drum length to quote (standard or extended for retention) | C12: =HMB!$C$80 -> 40 | D12: ft
B13: Airflow utilization | C13: =IF(ISNUMBER(Equipment!$C$8),HMB!$C$53/Equipment!$C$8,"") -> 0.73519971
B14: Evaporation utilization | C14: =IF(ISNUMBER(Equipment!$C$9),HMB!$C$9/Equipment!$C$9,"") -> 0.34488447
B15: BURNER
B16: Fired duty, design | C16: =HMB!$C$29/1000000 -> 7.2810294 | D16: MMBtu/hr
B17: Burner size with margin | C17: =Equipment!$C$16*(1+Inputs!$C$50) -> 8.7372353 | D17: MMBtu/hr
B18: Burner vs model maximum | C18: =IF(AND(ISNUMBER(Equipment!$C$10),Equipment!$C$10>0),IF(Equipment!$C$17<=Equipment!$C$10,"WITHIN MODEL BURNER RATING","EXCEEDS MODEL BURNER RATING - next size or bigger burner"),"model burner rating not entered") -> model burner rating not entered
B19: Burner face area at flux | C19: =Equipment!$C$17*1000000/Inputs!$C$52 -> 7281.0294 | D19: in² | E19: Drying Rates Calculator method
B20: 48 in × 12 in burners | C20: =Equipment!$C$19/576 -> 12.640676 | D20: count
B21: 3.375 in × 40 in burners | C21: =Equipment!$C$19/135 -> 53.933551 | D21: count
B22: Oven-pack style burner index (MMBtu/hr × 100) | C22: =ROUNDUP(Equipment!$C$17*100,-1) -> 880 | E22: 470 MOP was picked for 5.7 MMBtu/hr in Feb 2026; confirm against the vendor curve
B23: FAN, DUCT, CYCLONE
B24: Exhaust fan volume | C24: =HMB!$C$53 -> 12934.309 | D24: ACFM
B25: At temperature | C25: =Inputs!$C$38 -> 230 | D25: °F
B26: Fan brake horsepower | C26: =Equipment!$C$24*Inputs!$C$45/(6356*Inputs!$C$46) -> 37.568792 | D26: bhp | E26: Original DESIGN B29 used ACFM×18×5.2/33000×1.75
B27: Fan motor | C27: =INDEX(Tables!$B$4:$B$21,COUNTIF(Tables!$B$4:$B$21,"<"&Equipment!$C$26*1.15)+1) -> 50 | D27: hp | E27: Next standard motor above bhp × 1.15
B28: Exhaust duct diameter at duct velocity | C28: =SQRT(Equipment!$C$24/Inputs!$C$47*4/PI())*12 -> 21.778247 | D28: in
B29: Exhaust duct, even inches | C29: =CEILING(Equipment!$C$28,2) -> 22 | D29: in
B30: Actual velocity in selected duct | C30: =Equipment!$C$24/(PI()/4*(Equipment!$C$29/12)^2) -> 4899.7112 | D30: fpm
B31: Furnace-to-drum duct at inlet temperature | C31: =CEILING(SQRT(HMB!$C$60/Inputs!$C$47*4/PI())*12,2) -> 28 | D31: in
B32: Cyclone inlet area at inlet velocity | C32: =Equipment!$C$24/Inputs!$C$48*144 -> 564.40621 | D32: in² | E32: Hand ACFM and temperature to the MCE cyclone calculator for the model
B33: Cyclone barrel, Lapple proportions (inlet = D/2 × D/4) | C33: =SQRT(Equipment!$C$24/Inputs!$C$48/0.125)*12 -> 67.195607 | D33: in | E33: Indicative only
B34: MATERIAL HANDLING
B35: Dried product volume | C35: =HMB!$C$7/Inputs!$C$19/60 -> 1.2607843 | D35: ft³/min
B36: Wet feed volume | C36: =Inputs!$C$13/Inputs!$C$20/60 -> 1.9484848 | D36: ft³/min
B37: Discharge airlock (smallest with capacity ≥ product volume at 30% fill) | C37: =IFERROR(INDEX(Tables!$E$4:$E$13,COUNTIF(Tables!$H$4:$H$13,"<"&Equipment!$C$35)+1),"none in table") -> 1212
B38: Infeed airlock (≥ wet feed volume) | C38: =IFERROR(INDEX(Tables!$E$4:$E$13,COUNTIF(Tables!$H$4:$H$13,"<"&Equipment!$C$36)+1),"none in table") -> 1212
B39: Infeed screw (≥ wet feed ft³/hr at 30% fill) | C39: =IFERROR(INDEX(Tables!$J$4:$J$13,COUNTIF(Tables!$M$4:$M$13,"<"&Equipment!$C$36*60)+1),"none in table") -> 9 | D39: in
B40: ANNUAL
B41: Operating hours | C41: =Inputs!$C$59 -> 8400 | D41: h/yr
...

Sheet Tables
B1: REFERENCE TABLES
B3: Std motor hp | E3: Airlock size | F3: cf/rev | G3: rpm | H3: fill | I3: cf/min | J3: Screw size in | K3: cf/hr/rpm | L3: rpm | M3: cf/hr @30%
B4: 5 | E4: 1212 | F4: 0.68 | G4: 25 | H4: =F4*G4*0.3 -> 5.1 | J4: 4 | K4: 1.35 | L4: 70 | M4: =K4*L4*0.3 -> 28.35
B5: 7.5 | E5: 1616 | F5: 1.69 | G5: 43 | H5: =F5*G5*0.3 -> 21.801 | J5: 6 | K5: 4.91 | L5: 60 | M5: =K5*L5*0.3 -> 88.38
B6: 10 | E6: 2020 | F6: 3.2 | G6: 25 | H6: =F6*G6*0.3 -> 24 | J6: 9 | K6: 17.98 | L6: 55 | M6: =K6*L6*0.3 -> 296.67
B7: 15 | E7: 2040 | F7: 6.4 | G7: 20 | H7: =F7*G7*0.3 -> 38.4 | J7: 12 | K7: 42.5 | L7: 50 | M7: =K7*L7*0.3 -> 637.5
B8: 20 | E8: 2424 | F8: 5.94 | G8: 25 | H8: =F8*G8*0.3 -> 44.55 | J8: 14 | K8: 68.64 | L8: 50 | M8: =K8*L8*0.3 -> 1029.6
B9: 25 | E9: 3030 | F9: 11.2 | G9: 35 | H9: =F9*G9*0.3 -> 117.6 | J9: 16 | K9: 102.96 | L9: 35 | M9: =K9*L9*0.3 -> 1081.08
B10: 30 | E10: 3636 | F10: 19.9 | G10: 32 | H10: =F10*G10*0.3 -> 191.04 | J10: 18 | K10: 148.8 | L10: 45 | M10: =K10*L10*0.3 -> 2008.8
B11: 40 | E11: 4242 | F11: 32.1 | G11: 30 | H11: =F11*G11*0.3 -> 288.9 | J11: 20 | K11: 207.24 | L11: 40 | M11: =K11*L11*0.3 -> 2486.88
B12: 50 | E12: 4848 | F12: 48 | G12: 24 | H12: =F12*G12*0.3 -> 345.6 | J12: 24 | K12: 359.7 | L12: 40 | M12: =K12*L12*0.3 -> 4316.4
B13: 60 | E13: 6060 | F13: 93 | G13: 20 | H13: =F13*G13*0.3 -> 558 | J13: 30 | K13: 712.8 | L13: 35 | M13: =K13*L13*0.3 -> 7484.4
B14: 75 | E14: Source: original DESIGN K8:N19, 30% fill | J14: Source: original DESIGN K22:N32
B15: 100
B16: 125
B17: 150
B18: 200
B19: 250
B20: 300
B21: 350

Sheet Emissions
B1: EMISSIONS ESTIMATE · potential to emit · factors are placeholders to confirm against EPA AP-42
B3: INPUTS (blue)
B4: NOx factor | C4: 0.1 | D4: lb/MMBtu | H4: NG ~0.1; wood ~0.22; original COMB used 5.5% fuel N to NOx
B5: CO factor | C5: 0.08 | D5: lb/MMBtu | H5: NG ~0.08; wood ~0.6
B6: SO2 factor | C6: 0.0006 | D6: lb/MMBtu | H6: NG ~0.0006; wood 0.025
B7: VOC factor | C7: 0.9 | D7: lb/OD ton product | H7: Original Emiss. I29 (softwood shavings); AP-42 by species
B8: PM uncontrolled | C8: 3 | D8: lb/OD ton product | H8: Rotary wood dryer AP-42 range ~1–6; original used product×(1−0.99965)
B9: Cyclone collection efficiency | C9: 0.9 | D9: fraction | H9: Original 99.965% is not achievable with a cyclone
B10: PM10 share of PM | C10: 0.7 | D10: fraction | H10: Original 0.007%
B11: HAP share of VOC | C11: 0.15 | D11: fraction | H11: Original Emiss. I33
B12: RESULTS
B13: Pollutant | C13: lb/hr | D13: tons/yr at operating hours | E13: tons/yr PTE (8,760 h) | F13: lb/OD ton | G13: lb/MMBtu
B14: CO2 | C14: =HMB!$C$31*Inputs!$C$35 -> 1097.6426 | D14: =C14*Inputs!$C$59/2000 -> 4610.099 | E14: =C14*8760/2000 -> 4807.6747 | F14: =C14/(HMB!$C$5/2000) -> 1138.0432 | G14: =C14/(HMB!$C$29/1000000) -> 150.75377
B15: NOx | C15: =HMB!$C$29/1000000*Emissions!$C$4 -> 0.72810294 | D15: =C15*Inputs!$C$59/2000 -> 3.0580324 | E15: =C15*8760/2000 -> 3.1890909 | F15: =C15/(HMB!$C$5/2000) -> 0.75490196 | G15: =C15/(HMB!$C$29/1000000) -> 0.1
B16: CO | C16: =HMB!$C$29/1000000*Emissions!$C$5 -> 0.58248235 | D16: =C16*Inputs!$C$59/2000 -> 2.4464259 | E16: =C16*8760/2000 -> 2.5512727 | F16: =C16/(HMB!$C$5/2000) -> 0.60392157 | G16: =C16/(HMB!$C$29/1000000) -> 0.08
B17: SO2 | C17: =HMB!$C$29/1000000*Emissions!$C$6 -> 0.0043686176 | D17: =C17*Inputs!$C$59/2000 -> 0.018348194 | E17: =C17*8760/2000 -> 0.019134545 | F17: =C17/(HMB!$C$5/2000) -> 0.0045294118 | G17: =C17/(HMB!$C$29/1000000) -> 0.0006
B18: VOC | C18: =Emissions!$C$7*(HMB!$C$5/2000) -> 0.86805 | D18: =C18*Inputs!$C$59/2000 -> 3.64581 | E18: =C18*8760/2000 -> 3.802059 | F18: =C18/(HMB!$C$5/2000) -> 0.9 | G18: =C18/(HMB!$C$29/1000000) -> 0.11922078
B19: HAPs | C19: =Emissions!$C$11*Emissions!$C$7*(HMB!$C$5/2000) -> 0.1302075 | D19: =C19*Inputs!$C$59/2000 -> 0.5468715 | E19: =C19*8760/2000 -> 0.57030885 | F19: =C19/(HMB!$C$5/2000) -> 0.135 | G19: =C19/(HMB!$C$29/1000000) -> 0.017883117
B20: PM after cyclone | C20: =Emissions!$C$8*(HMB!$C$5/2000)*(1-Emissions!$C$9) -> 0.28935 | D20: =C20*Inputs!$C$59/2000 -> 1.21527 | E20: =C20*8760/2000 -> 1.267353 | F20: =C20/(HMB!$C$5/2000) -> 0.3 | G20: =C20/(HMB!$C$29/1000000) -> 0.03974026
B21: PM10 after cyclone | C21: =Emissions!$C$8*(HMB!$C$5/2000)*(1-Emissions!$C$9)*Emissions!$C$10 -> 0.202545 | D21: =C21*Inputs!$C$59/2000 -> 0.850689 | E21: =C21*8760/2000 -> 0.8871471 | F21: =C21/(HMB!$C$5/2000) -> 0.21 | G21: =C21/(HMB!$C$29/1000000) -> 0.027818182

Sheet Biochar Reactor
B1: BIOCHAR REACTOR · slow pyrolysis / torrefaction option · imperial
B2: Mass and energy balance for an indirect-fired rotary reactor. Blue = input. Volatiles are burned in an afterburner; surplus heat can be credited to the dryer (Inputs: coupling = Yes).
B4: INPUTS | G4: CHAR YIELD GUIDE (wood, dry basis)
B5: Feed source | C5: Dryer product | E5: Dryer product (takes rate and moisture from HMB) or Manual (enter below) | G5: Solids temp °F | H5: Yield
B6: Manual feed rate, wet | C6: 2000 | D6: lb/hr | E6: Used only when source = Manual | G6: 480 | H6: 0.85
B7: Manual feed moisture, wet basis | C7: 0.1 | G7: 570 | H7: 0.7
B8: Feed temperature | C8: 150 | D8: °F | E8: Dryer product arrives hot; ambient if from storage | G8: 750 | H8: 0.4
B9: Feed heating value, dry basis | C9: 8000 | D9: Btu/lb | E9: Wood ~8,000–8,600 dry | G9: 840 | H9: 0.33
B10: Ash, dry basis | C10: 0.02 | G10: 932 | H10: 0.28
B11: Reactor solids temperature | C11: 932 | D11: °F | E11: 500 °C = 932 °F slow pyrolysis; torrefaction 480–570 °F | G11: 1100 | H11: 0.24
B12: Char yield, dry basis | C12: 0.28 | D12: fraction of dry feed | E12: MCE default, confirmed J. Shipley 9 Sep 2026. See table at right; Prozus report assumed 1.0, which is why its 67% product was wrong | G12: 1300 | H12: 0.21
B13: Char heating value | C13: 12500 | D13: Btu/lb | E13: Wood char 11,500–13,500 dry | G13: Torrefaction 480–570 °F keeps 70–85%; slow pyrolysis 840–1,100 °F gives 24–33%. Confirm on a sample.
B14: Reaction heat | C14: 100 | D14: Btu/lb dry feed | E14: MCE default, confirmed J. Shipley 9 Sep 2026; + endothermic, wood slow pyrolysis roughly 0 to +200
B15: Specific heat, dry feed | C15: 0.35 | D15: Btu/lb·°F
B16: Volatile gas temperature leaving reactor | C16: 900 | D16: °F
B17: Reactor shell loss | C17: 0.05 | D17: fraction of demand | E17: Indirect fired, insulated
B18: Afterburner combustion efficiency | C18: 0.9 | D18: fraction | E18: Share of volatile energy recovered as hot gas
B19: Afterburner flue gas temperature | C19: 1600 | D19: °F | E19: Sets the gas volume available to the reactor jacket and dryer
B20: Jacket gas outlet temperature | C20: 700 | D20: °F | E20: Flue gas leaves the reactor jacket above the solids temperature
B21: Residence time | C21: 30 | D21: min | E21: Slow pyrolysis 20–60 min; torrefaction 15–30
B22: Reactor fill | C22: 0.15 | D22: fraction
B23: Feed bulk density | C23: 8 | D23: lb/ft³
B24: Reactor drum diameter | C24: 5 | D24: ft | E24: Pick; length is sized below. Go up a size if L/D exceeds 10
B25: Allowable indirect shell heat flux | C25: 4000 | D25: Btu/hr·ft² | E25: MCE default, confirmed J. Shipley 9 Sep 2026; indirect rotary reactors 2,000–6,000
B26: MASS BALANCE
B27: Feed, wet | C27: =IF('Biochar Reactor'!$C$5="Dryer product",HMB!$C$7,'Biochar Reactor'!$C$6) -> 2269.4118 | D27: lb/hr
B28: Feed moisture | C28: =IF('Biochar Reactor'!$C$5="Dryer product",Inputs!$C$15,'Biochar Reactor'!$C$7) -> 0.15
B29: Dry feed | C29: ='Biochar Reactor'!$C$27*(1-'Biochar Reactor'!$C$28) -> 1929 | D29: lb/hr
B30: Water in feed | C30: ='Biochar Reactor'!$C$27*'Biochar Reactor'!$C$28 -> 340.41176 | D30: lb/hr
B31: Biochar out | C31: ='Biochar Reactor'!$C$29*'Biochar Reactor'!$C$12 -> 540.12 | D31: lb/hr
B32: Biochar out | C32: ='Biochar Reactor'!$C$31/2000 -> 0.27006 | D32: TPH
B33: Volatiles + gas | C33: ='Biochar Reactor'!$C$29-'Biochar Reactor'!$C$31 -> 1388.88 | D33: lb/hr
B34: Char as share of wet feed | C34: ='Biochar Reactor'!$C$31/'Biochar Reactor'!$C$27 -> 0.238
B35: ENERGY
B36: Heat dry feed to reactor temperature | C36: ='Biochar Reactor'!$C$29*'Biochar Reactor'!$C$15*('Biochar Reactor'!$C$11-'Biochar Reactor'!$C$8) -> 527967.3 | D36: Btu/hr
B37: Evaporate and superheat feed moisture | C37: ='Biochar Reactor'!$C$30*(1.01*(212-'Biochar Reactor'!$C$8)+970.4+0.45*('Biochar Reactor'!$C$16-212)) -> 457043.64 | D37: Btu/hr
B38: Reaction heat | C38: ='Biochar Reactor'!$C$29*'Biochar Reactor'!$C$14 -> 192900 | D38: Btu/hr
B39: Heat volatiles to gas outlet temperature (above solids) | C39: ='Biochar Reactor'!$C$33*0.45*MAX(0,'Biochar Reactor'!$C$16-'Biochar Reactor'!$C$11) -> 0 | D39: Btu/hr
B40: Reactor heat demand incl. shell loss | C40: =('Biochar Reactor'!$C$36+'Biochar Reactor'!$C$37+'Biochar Reactor'!$C$38+'Biochar Reactor'!$C$39)*(1+'Biochar Reactor'!$C$17) -> 1236806.5 | D40: Btu/hr
B41: Reactor heat demand | C41: ='Biochar Reactor'!$C$40/1000000 -> 1.2368065 | D41: MMBtu/hr
...

Sheet Metric
B1: METRIC SUMMARY · converted from the imperial sheets
B3: MASS
B4: Wet feed | C4: =Inputs!$C$13/2.20462 -> 2916.6024 | D4: kg/h
B5: Wet feed | C5: =Inputs!$C$13/2.20462/1000 -> 2.9166024 | D5: t/h
B6: Dried product | C6: =HMB!$C$7/2.20462 -> 1029.3891 | D6: kg/h
B7: Water evaporated | C7: =HMB!$C$9/2.20462 -> 1887.2133 | D7: kg/h
B8: Moisture in / out (wet basis) | C8: =TEXT(Inputs!$C$14,"0.0%")&" / "&TEXT(Inputs!$C$15,"0.0%") -> 70.0% / 15.0%
B9: ENERGY
B10: Theoretical energy per kg water | C10: =HMB!$C$13*2.326 -> 2555.5064 | D10: kJ/kg
B11: MCE energy factor | C11: =HMB!$C$14*2.326 -> 4070.5 | D11: kJ/kg
B12: Design fired duty | C12: =HMB!$C$29*1.05506/1000000 -> 7.6819229 | D12: GJ/h
B13: Design fired duty | C13: =HMB!$C$29*0.293071/1000 -> 2133.8586 | D13: kW
B14: Fuel rate | C14: =HMB!$C$31/2.20462 -> 165.96097 | D14: kg/h
B15: Fuel heating value | C15: =Inputs!$C$31*2.326 -> 46287.4 | D15: kJ/kg
B16: TEMPERATURES
B17: Product in / out | C17: =TEXT((Inputs!$C$16-32)*5/9,"0")&" / "&TEXT((Inputs!$C$17-32)*5/9,"0") -> 29 / 82 | D17: °C
B18: Gas in / out | C18: =TEXT((Inputs!$C$36-32)*5/9,"0")&" / "&TEXT((Inputs!$C$38-32)*5/9,"0") -> 482 / 110 | D18: °C
B19: GAS
B20: Hot gas to dryer | C20: =HMB!$C$41/2.20462 -> 15196.12 | D20: kg/h
B21: Exhaust total | C21: =HMB!$C$48/2.20462 -> 19171.357 | D21: kg/h
B22: Exhaust volume at exhaust temperature | C22: =HMB!$C$53*1.69901 -> 21975.52 | D22: m³/h
B23: Exhaust volume, normal (0 °C, 1 atm) | C23: =HMB!$C$54*1.69901*273.15/294.26 -> 15962.688 | D23: Nm³/h
B24: EQUIPMENT
B25: Selected dryer | C25: =Equipment!$C$4 -> XD-96 (8'×40')
B26: Drum diameter × length | C26: =IF(ISNUMBER(Equipment!$C$5),TEXT(Equipment!$C$5*0.3048,"0.00")&" × "&TEXT(Equipment!$C$6*0.3048,"0.0"),"") -> 2.44 × 12.2 | D26: m
B27: Burner size with margin | C27: =Equipment!$C$17*0.293071 -> 2.5606303 | D27: MW
B28: Fan motor | C28: =Equipment!$C$27*0.7457 -> 37.285 | D28: kW
B29: Exhaust duct | C29: =Equipment!$C$29*25.4 -> 558.8 | D29: mm
B30: Fan static pressure | C30: =Inputs!$C$45*249.09 -> 2989.08 | D30: Pa

Sheet Cases
B1: REFERENCE CASES · copy a column into Inputs to rerun
B3: Input | C3: Track B (this file default) | D3: Prozus track A | E3: LETEK digestate case A | F3: 6x24 expected (2005 file)
B4: Material | C4: Wood shavings | D4: Biomass | E4: Chicken manure digestate cake | F4: Grapeskins
B5: Wet feed lb/hr | C5: 3000 | D5: 3000 | E5: 6430 | F5: 4300
B6: Moisture in | C6: 0.5 | D6: 0.35 | E6: 0.7 | F6: 0.5
B7: Moisture out | C7: 0.1 | D7: 0.1 | E7: 0.15 | F7: 0.1
B8: Product temp in °F | C8: 60 | D8: 60 | E8: 85 | F8: 70
B9: Product temp out °F | C9: 200 | D9: 176 | E9: 180 | F9: 160
B10: Dryer inlet gas °F | C10: 600 | D10: 588 | E10: 1100 | F10: 600
B11: Exhaust gas °F | C11: 180 | D11: 180 | E11: 230 | F11: 220
B12: Energy factor | C12: 1750 | D12: 1750 | E12: 1750 | F12: 1750
B13: Fuel | C13: Natural Gas | D13: Dry Wood | E13: Biogas 55% CH4 | F13: Natural Gas
B14: Note | C14: Original Input sheet basis | D14: Prozus used feed at 100 °C and solids out at 375 °C; not reproduced | E14: From LETEK PFD Rev A, 140 MT/day, 24 h | F14: 624DryerExpected20051205.xlsx: 8,400 ACFM, 3.5 MMBtu/h observed
